<?xml version="1.0"?>
<sdf version="1.5">
	<!-- This file uses inertial values for the spherical joints from the force-torque sensor tutorial in Gazebo -->

<model name = "stewart">
	<plugin name="joint_controller" filename="libjoint_controller.so"/>
  <plugin name="gazebo_ros_control" filename="libgazebo_ros_control.so"/>

	<joint name = "piston1_prismatic_joint" type = "prismatic" >
		<parent> piston1_cylinder_link </parent>
		<child> piston1_shaft_link </child>
		<pose> 0 0 0 0 0 0 </pose>
		<axis>
			<xyz> 0 0 1 </xyz>
			<limit>
				<lower> 0 </lower>
				<upper> 1.9291197998702527 </upper>
				<velocity> 1 </velocity>
			</limit>
		</axis>
		<sensor name="wrench_sensor" type="force_torque">
				<update_rate>30</update_rate>
				<always_on>true</always_on>
				<visualize>false</visualize>
		</sensor>
	</joint>

	<joint name = "piston2_prismatic_joint" type = "prismatic" >
		<parent> piston2_cylinder_link </parent>
		<child> piston2_shaft_link </child>
		<pose> 0 0 0 0 0 0 </pose>
		<axis>
			<xyz> 0 0 1 </xyz>
			<limit>
				<lower> 0 </lower>
				<upper> 1.9291197998702527 </upper>
				<velocity> 1 </velocity>
			</limit>
		</axis>
		<sensor name="wrench_sensor" type="force_torque">
				<update_rate>30</update_rate>
				<always_on>true</always_on>
				<visualize>false</visualize>
		</sensor>
	</joint>

	<joint name = "piston3_prismatic_joint" type = "prismatic" >
		<parent> piston3_cylinder_link </parent>
		<child> piston3_shaft_link </child>
		<pose> 0 0 0 0 0 0 </pose>
		<axis>
			<xyz> 0 0 1 </xyz>
			<limit>
				<lower> 0 </lower>
				<upper> 1.9291197998702527 </upper>
				<velocity> 1 </velocity>
			</limit>
		</axis>
		<sensor name="wrench_sensor" type="force_torque">
				<update_rate>30</update_rate>
				<always_on>true</always_on>
				<visualize>false</visualize>
		</sensor>
	</joint>

	<joint name = "piston4_prismatic_joint" type = "prismatic" >
		<parent> piston4_cylinder_link </parent>
		<child> piston4_shaft_link </child>
		<pose> 0 0 0 0 0 0 </pose>
		<axis>
			<xyz> 0 0 1 </xyz>
			<limit>
				<lower> 0 </lower>
				<upper> 1.9291197998702527 </upper>
				<velocity> 1 </velocity>
			</limit>
		</axis>
		<sensor name="wrench_sensor" type="force_torque">
				<update_rate>30</update_rate>
				<always_on>true</always_on>
				<visualize>false</visualize>
		</sensor>
	</joint>

	<joint name = "piston5_prismatic_joint" type = "prismatic" >
		<parent> piston5_cylinder_link </parent>
		<child> piston5_shaft_link </child>
		<pose> 0 0 0 0 0 0 </pose>
		<axis>
			<xyz> 0 0 1 </xyz>
			<limit>
				<lower> 0 </lower>
				<upper> 1.9291197998702527 </upper>
				<velocity> 1 </velocity>
			</limit>
		</axis>
		<sensor name="wrench_sensor" type="force_torque">
				<update_rate>30</update_rate>
				<always_on>true</always_on>
				<visualize>false</visualize>
		</sensor>
	</joint>

	<joint name = "piston6_prismatic_joint" type = "prismatic" >
		<parent> piston6_cylinder_link </parent>
		<child> piston6_shaft_link </child>
		<pose> 0 0 0 0 0 0 </pose>
		<axis>
			<xyz> 0 0 1 </xyz>
			<limit>
				<lower> 0 </lower>
				<upper> 1.9291197998702527 </upper>
				<velocity> 1 </velocity>
			</limit>
		</axis>
		<sensor name="wrench_sensor" type="force_torque">
				<update_rate>30</update_rate>
				<always_on>true</always_on>
				<visualize>false</visualize>
		</sensor>
	</joint>

	<joint name = "butt_ball1_joint" type = "revolute" >
		<parent> base_link </parent>
		<child> butt_ball1_link </child>
		<pose> 0 0 0 0 0 0 </pose>
		<axis>
			<xyz> 0 1 0 </xyz>
			<limit>
				<lower> -0.786 </lower>
				<upper> 0.786 </upper>fixed
				<velocity> 0.1 </velocity>
			</limit>
		</axis>
		<sensor name="wrench_sensor" type="force_torque">
		  <force_torque>
		    <!-- <frame>parent</frame>
		    <measure_direction>parent_to_child</measure_direction> -->
				<always_on>true</always_on>
				<visualize>false</visualize>
				<update_rate>30</update_rate>
			</force_torque>
			<always_on>true</always_on>
			<visualize>false</visualize>
		</sensor>
	</joint>

	<joint name = "butt_ball2_joint" type = "revolute" >
		<parent> base_link </parent>
		<child> butt_ball2_link </child>
		<pose> 0 0 0 0 0 0 </pose>
		<axis>
			<xyz> 0 1 0 </xyz>
			<limit>
				<lower> -0.786 </lower>
				<upper> 0.786 </upper>
				<velocity> 0.1 </velocity>
			</limit>
		</axis>
		<sensor name="wrench_sensor" type="force_torque">
				<update_rate>30</update_rate>
				<always_on>true</always_on>
				<visualize>false</visualize>
		</sensor>
	</joint>

	<joint name = "butt_ball3_joint" type = "revolute" >
		<parent> base_link </parent>
		<child> butt_ball3_link </child>
		<pose> 0 0 0 0 0 0 </pose>
		<axis>
			<xyz> 0 1 0 </xyz>
			<limit>
				<lower> -0.786 </lower>
				<upper> 0.786 </upper>
				<velocity> 0.1 </velocity>
			</limit>
		</axis>
		<sensor name="wrench_sensor" type="force_torque">
				<update_rate>30</update_rate>
				<always_on>true</always_on>
				<visualize>false</visualize>
		</sensor>
	</joint>

	<joint name = "butt_ball4_joint" type = "revolute" >
		<parent> base_link </parent>
		<child> butt_ball4_link </child>
		<pose> 0 0 0 0 0 0 </pose>
		<axis>
			<xyz> 0 1 0 </xyz>
			<limit>
				<lower> -0.786 </lower>
				<upper> 0.786 </upper>
				<velocity> 0.1 </velocity>
			</limit>
		</axis>
		<sensor name="wrench_sensor" type="force_torque">
				<update_rate>30</update_rate>
				<always_on>true</always_on>
				<visualize>false</visualize>
		</sensor>
	</joint>

	<joint name = "butt_ball5_joint" type = "revolute" >
		<parent> base_link </parent>
		<child> butt_ball5_link </child>
		<pose> 0 0 0 0 0 0 </pose>
		<axis>
			<xyz> 0 1 0 </xyz>
			<limit>
				<lower> -0.786 </lower>
				<upper> 0.786 </upper>
				<velocity> 0.1 </velocity>
			</limit>
		</axis>
		<sensor name="wrench_sensor" type="force_torque">
				<update_rate>30</update_rate>
				<always_on>true</always_on>
				<visualize>false</visualize>
		</sensor>
	</joint>

	<joint name = "butt_ball6_joint" type = "revolute" >
		<parent> base_link </parent>
		<child> butt_ball6_link </child>
		<pose> 0 0 0 0 0 0 </pose>
		<axis>
			<xyz> 0 1 0 </xyz>
			<limit>
				<lower> -0.786 </lower>
				<upper> 0.786 </upper>
				<velocity> 0.1 </velocity>
			</limit>
		</axis>
		<sensor name="wrench_sensor" type="force_torque">
				<update_rate>30</update_rate>
				<always_on>true</always_on>
				<visualize>false</visualize>
		</sensor>
	</joint>

	<joint name = "top_ball1_joint" type = "revolute" >
		<parent> platform_link </parent>
		<child> top_ball1_link </child>
		<pose> 0 0 0 0 0 0 </pose>
		<axis>
			<xyz> 0 0 1 </xyz>
			<limit>
				<lower> -0.786 </lower>
				<upper> 0.786 </upper>
				<velocity> 0.1 </velocity>
			</limit>
		</axis>
		<sensor name="wrench_sensor" type="force_torque">
				<update_rate>30</update_rate>
				<always_on>true</always_on>
				<visualize>false</visualize>
		</sensor>
	</joint>

	<joint name = "top_ball2_joint" type = "revolute" >
		<parent> platform_link </parent>
		<child> top_ball2_link </child>
		<pose> 0 0 0 0 0 0 </pose>
		<axis>
			<xyz> 0 0 1 </xyz>
			<limit>
				<lower> -0.786 </lower>
				<upper> 0.786 </upper>
				<velocity> 0.1 </velocity>
			</limit>
		</axis>
		<sensor name="wrench_sensor" type="force_torque">
				<update_rate>30</update_rate>
				<always_on>true</always_on>
				<visualize>false</visualize>
		</sensor>
	</joint>

	<joint name = "top_ball3_joint" type = "revolute" >
		<parent> platform_link </parent>
		<child> top_ball3_link </child>
		<pose> 0 0 0 0 0 0 </pose>
		<axis>
			<xyz> 0 0 1 </xyz>
			<limit>
				<lower> -0.786 </lower>
				<upper> 0.786 </upper>
				<velocity> 0.1 </velocity>
			</limit>
		</axis>
		<sensor name="wrench_sensor" type="force_torque">
				<update_rate>30</update_rate>
				<always_on>true</always_on>
				<visualize>false</visualize>
		</sensor>
	</joint>

	<joint name = "top_ball4_joint" type = "revolute" >
		<parent> platform_link </parent>
		<child> top_ball4_link </child>
		<pose> 0 0 0 0 0 0 </pose>
		<axis>
			<xyz> 0 0 1 </xyz>
			<limit>
				<lower> -0.786 </lower>
				<upper> 0.786 </upper>
				<velocity> 0.1 </velocity>
			</limit>
		</axis>
		<sensor name="wrench_sensor" type="force_torque">
				<update_rate>30</update_rate>
				<always_on>true</always_on>
				<visualize>false</visualize>
		</sensor>
	</joint>

	<joint name = "top_ball5_joint" type = "revolute" >
		<parent> platform_link </parent>
		<child> top_ball5_link </child>
		<pose> 0 0 0 0 0 0 </pose>
		<axis>
			<xyz> 0 0 1 </xyz>
			<limit>
				<lower> -0.786 </lower>
				<upper> 0.786 </upper>
				<velocity> 0.1 </velocity>
			</limit>
		</axis>
		<sensor name="wrench_sensor" type="force_torque">
				<update_rate>30</update_rate>
				<always_on>true</always_on>
				<visualize>false</visualize>
		</sensor>
	</joint>

	<joint name = "top_ball6_joint" type = "revolute" >
		<parent> platform_link </parent>
		<child> top_ball6_link </child>
		<pose> 0 0 0 0 0 0 </pose>
		<axis>
			<xyz> 0 0 1 </xyz>
			<limit>
				<lower> -0.786 </lower>
				<upper> 0.786 </upper>
				<velocity> 0.1 </velocity>
			</limit>
		</axis>
		<sensor name="wrench_sensor" type="force_torque">
				<update_rate>30</update_rate>
				<always_on>true</always_on>
				<visualize>false</visualize>
		</sensor>
	</joint>

	<joint name = "piston1_bottom_pitch_joint" type = "revolute" >
		<parent> butt_ball1_link </parent>
		<child> piston1_cylinder_link </child>
		<pose> 0 0 -0.9645598999351264 0 0 0 </pose>
		<axis>
			<xyz> 1 0 0 </xyz>
			<limit>
				<lower> -0.786 </lower>
				<upper> 0.786 </upper>
			</limit>
		</axis>
		<sensor name="wrench_sensor" type="force_torque">
				<update_rate>30</update_rate>
				<always_on>true</always_on>
				<visualize>false</visualize>
		</sensor>
	</joint>

	<joint name = "piston2_bottom_pitch_joint" type = "revolute" >
		<parent> butt_ball2_link </parent>
		<child> piston2_cylinder_link </child>
		<pose> 0 0 -0.9645598999351264 0 0 0</pose>
		<axis>
			<xyz> 1 0 0 </xyz>
			<limit>
				<lower> -0.786 </lower>
				<upper> 0.786 </upper>
			</limit>
		</axis>
		<sensor name="wrench_sensor" type="force_torque">
				<update_rate>30</update_rate>
				<always_on>true</always_on>
				<visualize>false</visualize>
		</sensor>
	</joint>

	<joint name = "piston3_bottom_pitch_joint" type = "revolute" >
		<parent> butt_ball3_link </parent>
		<child> piston3_cylinder_link </child>
		<pose> 0 0 -0.9645598999351264 0 0 0 </pose>
		<axis>
			<xyz> 1 0 0 </xyz>
			<limit>
				<lower> -0.786 </lower>
				<upper> 0.786 </upper>
			</limit>
		</axis>
		<sensor name="wrench_sensor" type="force_torque">
				<update_rate>30</update_rate>
				<always_on>true</always_on>
				<visualize>false</visualize>
		</sensor>
	</joint>

	<joint name = "piston4_bottom_pitch_joint" type = "revolute" >
		<parent> butt_ball4_link </parent>
		<child> piston4_cylinder_link </child>
		<pose> 0 0 -0.9645598999351264 0 0 0 </pose>
		<axis>
			<xyz> 1 0 0 </xyz>
			<limit>
				<lower> -0.786 </lower>
				<upper> 0.786 </upper>
			</limit>
		</axis>
		<sensor name="wrench_sensor" type="force_torque">
				<update_rate>30</update_rate>
				<always_on>true</always_on>
				<visualize>false</visualize>
		</sensor>
	</joint>

	<joint name = "piston5_bottom_pitch_joint" type = "revolute" >
		<parent> butt_ball5_link </parent>
		<child> piston5_cylinder_link </child>
		<pose> 0 0 -0.9645598999351264 0 0 0 </pose>
		<axis>
			<xyz> 1 0 0 </xyz>
			<limit>
				<lower> -0.786 </lower>
				<upper> 0.786 </upper>
			</limit>
		</axis>
		<sensor name="wrench_sensor" type="force_torque">
				<update_rate>30</update_rate>
				<always_on>true</always_on>
				<visualize>false</visualize>
		</sensor>
	</joint>

	<joint name = "piston6_bottom_pitch_joint" type = "revolute" >
		<parent> butt_ball6_link </parent>
		<child> piston6_cylinder_link </child>
		<pose> 0 0 -0.9645598999351264 0 0 0 </pose>
		<axis>
			<xyz> 1 0 0 </xyz>
			<limit>
				<lower> -0.786 </lower>
				<upper> 0.786 </upper>
			</limit>
		</axis>
		<sensor name="wrench_sensor" type="force_torque">
				<update_rate>30</update_rate>
				<always_on>true</always_on>
				<visualize>false</visualize>
		</sensor>
	</joint>

	<joint name = "piston1_top_ball_joint" type = "revolute" >
		<parent> top_ball1_link </parent>
		<child> piston1_shaft_link </child>
		<pose> 0 0 0.9645598999351264 0 0 0 </pose>
		<axis>
			<xyz> 1 0 0 </xyz>
			<limit>
				<lower> -0.786 </lower>
				<upper> 0.786 </upper>
			</limit>
		</axis>
		<sensor name="wrench_sensor" type="force_torque">
				<update_rate>30</update_rate>
				<always_on>true</always_on>
				<visualize>false</visualize>
		</sensor>
	</joint>

	<joint name = "piston2_top_ball_joint" type = "revolute" >
		<parent> top_ball2_link </parent>
		<child> piston2_shaft_link </child>
		<pose> 0 0 0.9645598999351264 0 0 0</pose>
		<axis>
			<xyz> 1 0 0 </xyz>
			<limit>
				<lower> -0.786 </lower>
				<upper> 0.786 </upper>
			</limit>
		</axis>
		<sensor name="wrench_sensor" type="force_torque">
				<update_rate>30</update_rate>
				<always_on>true</always_on>
				<visualize>false</visualize>
		</sensor>
	</joint>

	<joint name = "piston3_top_ball_joint" type = "revolute" >
		<parent> top_ball3_link </parent>
		<child> piston3_shaft_link </child>
		<pose> 0 0 0.9645598999351264 0 0 0 </pose>
		<axis>
			<xyz> 1 0 0 </xyz>
			<limit>
				<lower> -0.786 </lower>
				<upper> 0.786 </upper>
			</limit>
		</axis>
		<sensor name="wrench_sensor" type="force_torque">
				<update_rate>30</update_rate>
				<always_on>true</always_on>
				<visualize>false</visualize>
		</sensor>
	</joint>

	<joint name = "piston4_top_ball_joint" type = "revolute" >
		<parent> top_ball4_link </parent>
		<child> piston4_shaft_link </child>
		<pose> 0 0 0.9645598999351264 0 0 0 </pose>
		<axis>
			<xyz> 1 0 0 </xyz>
			<limit>
				<lower> -0.786 </lower>
				<upper> 0.786 </upper>
			</limit>
		</axis>
		<sensor name="wrench_sensor" type="force_torque">
				<update_rate>30</update_rate>
				<always_on>true</always_on>
				<visualize>false</visualize>
		</sensor>
	</joint>

	<joint name = "piston5_top_ball_joint" type = "revolute" >
		<parent> top_ball5_link </parent>
		<child> piston5_shaft_link </child>
		<pose> 0 0 0.9645598999351264 0 0 0 </pose>
		<axis>
			<xyz> 1 0 0 </xyz>
			<limit>
				<lower> -0.786 </lower>
				<upper> 0.786 </upper>
			</limit>
		</axis>
		<sensor name="wrench_sensor" type="force_torque">
				<update_rate>30</update_rate>
				<always_on>true</always_on>
				<visualize>false</visualize>
		</sensor>
	</joint>

	<joint name = "piston6_top_ball_joint" type = "revolute" >
		<parent> top_ball6_link </parent>
		<child> piston6_shaft_link </child>
		<pose> 0 0 0.9645598999351264 0 0 0 </pose>
		<axis>
			<xyz> 1 0 0 </xyz>
			<limit>
				<lower> -0.786 </lower>
				<upper> 0.786 </upper>
			</limit>
		</axis>
		<sensor name="wrench_sensor" type="force_torque">
				<update_rate>30</update_rate>
				<always_on>true</always_on>
				<visualize>false</visualize>
		</sensor>
	</joint>

	<link name = "base_link" >
		<pose> 0 0 0.125 0 0 0 </pose>
		<inertial>
			<mass> 1000.0 </mass>
			<inertia>
				<ixx> 255.2083333333333 </ixx>
				<ixy> 0.0 </ixy>
				<ixz> 0.0</ixz>
				<iyy> 255.2083333333333 </iyy>
				<iyz> 0.0 </iyz>
				<izz> 500.0 </izz>
			</inertia>
		</inertial>

		<visual name = "base_link_visual" >
			<geometry>
				<cylinder>
					<radius> 1.0 </radius>
					<length> 0.25 </length>
				</cylinder>
			</geometry>
			<material>
				<ambient>.2 .2 .9 1</ambient>
        <diffuse>.2 .2 0.2 1</diffuse>
        <specular>0 0 0 0</specular>
        <emissive>0 0 0 1</emissive>
			</material>
		</visual>

		<collision name = "base_link_collision" >
			<geometry>
				<cylinder>
					<radius> 1.0 </radius>
					<length> 0.25 </length>
				</cylinder>
			</geometry>
		</collision>
	</link>

	<link name = "platform_link" >
		<pose> 0 0 2.125 0 0 0 </pose>
		<inertial>
			<mass> 10.0 </mass>
			<inertia>
				<ixx> 2.552083333333333 </ixx>
				<ixy> 0.0 </ixy>
				<ixz> 0.0</ixz>
				<iyy> 2.552083333333333 </iyy>
				<iyz> 0.0 </iyz>
				<izz> 5.0 </izz>
			</inertia>
		</inertial>

		<visual name = "platform_link_visual" >
			<geometry>
				<cylinder>
					<radius> 1.0 </radius>
					<length> 0.1 </length>
				</cylinder>
			</geometry>
			<material>
          <ambient>0.8 0.4 0.8 1</ambient>
          <diffuse>0.8 0.4 0.2 1</diffuse>
          <specular>0 0 0 0</specular>
          <emissive>0 0 0 1</emissive>
			</material>
		</visual>

		<collision name = "platform_link_collision" >
			<geometry>
				<cylinder>
					<radius> 1.0 </radius>
					<length> 0.1 </length>
				</cylinder>
			</geometry>
		</collision>
	</link>

	<link name = "butt_ball1_link" >
		<pose> -0.10094113843523252 0.7998817953744161 0.25 0 0 2.0945 </pose>
		<inertial>
			<mass> 0.5 </mass>
			<inertia>
				<ixx> 0.0020000000000000005 </ixx>
				<ixy> 0.0 </ixy>
				<ixz> 0.0 </ixz>
				<iyy> 0.0020000000000000005 </iyy>
				<iyz> 0.0 </iyz>
				<izz> 0.0020000000000000005 </izz>
			</inertia>
		</inertial>

		<visual name = "butt_ball1_link_visual" >
			<geometry>
				<sphere>
					<radius> 0.1" </radius>
				</sphere>
			</geometry>
		</visual>

		<collision name = "butt_ball1_link_collision" >
			<geometry>
				<sphere>
					<radius> 0.1" </radius>
				</sphere>
			</geometry>
		</collision>
	</link>

	<link name = "butt_ball2_link" >
		<pose> 0.10061530109167109 0.7999228470210314 0.25 0 0 -2.0945 </pose>
		<inertial>
			<mass> 0.5 </mass>
			<inertia>
				<ixx> 0.0020000000000000005 </ixx>
				<ixy> 0.0 </ixy>
				<ixz> 0.0 </ixz>
				<iyy> 0.0020000000000000005 </iyy>
				<iyz> 0.0 </iyz>
				<izz> 0.0020000000000000005 </izz>
			</inertia>
		</inertial>

		<visual name = "butt_ball2_link_visual" >
			<geometry>
				<sphere>
					<radius> 0.1" </radius>
				</sphere>
			</geometry>
		</visual>

		<collision name = "butt_ball2_link_collision" >
			<geometry>
				<sphere>
					<radius> 0.1" </radius>
				</sphere>
			</geometry>
		</collision>
	</link>

	<link name = "butt_ball3_link" >
		<pose> 0.7429993434805581 -0.3129728032712424 0.25 0 0 0 </pose>
		<inertial>
			<mass> 0.5 </mass>
			<inertia>
				<ixx> 0.0020000000000000005 </ixx>
				<ixy> 0.0 </ixy>
				<ixz> 0.0 </ixz>
				<iyy> 0.0020000000000000005 </iyy>
				<iyz> 0.0 </iyz>
				<izz> 0.0020000000000000005 </izz>
			</inertia>
		</inertial>

		<visual name = "butt_ball3_link_visual" >
			<geometry>
				<sphere>
					<radius> 0.1" </radius>
				</sphere>
			</geometry>
		</visual>

		<collision name = "butt_ball3_link_collision" >
			<geometry>
				<sphere>
					<radius> 0.1" </radius>
				</sphere>
			</geometry>
		</collision>
	</link>

	<link name = "butt_ball4_link" >
		<pose> 0.6421510948171859 -0.4874853550878114 0.25 0 0 2.0945 </pose>
		<inertial>
			<mass> 0.5 </mass>
			<inertia>
				<ixx> 0.0020000000000000005 </ixx>
				<ixy> 0.0 </ixy>
				<ixz> 0.0 </ixz>
				<iyy> 0.0020000000000000005 </iyy>
				<iyz> 0.0 </iyz>
				<izz> 0.0020000000000000005 </izz>
			</inertia>
		</inertial>

		<visual name = "butt_ball4_link_visual" >
			<geometry>
				<sphere>
					<radius> 0.1" </radius>
				</sphere>
			</geometry>
		</visual>

		<collision name = "butt_ball4_link_collision" >
			<geometry>
				<sphere>
					<radius> 0.1" </radius>
				</sphere>
			</geometry>
		</collision>
	</link>

	<link name = "butt_ball5_link" >
		<pose> -0.6433227790696778 -0.48593806388269956 0.25 0 0 -2.0945 </pose>
		<inertial>
			<mass> 0.5 </mass>
			<inertia>
				<ixx> 0.0020000000000000005 </ixx>
				<ixy> 0.0 </ixy>
				<ixz> 0.0 </ixz>
				<iyy> 0.0020000000000000005 </iyy>
				<iyz> 0.0 </iyz>
				<izz> 0.0020000000000000005 </izz>
			</inertia>
		</inertial>

		<visual name = "butt_ball5_link_visual" >
			<geometry>
				<sphere>
					<radius> 0.1" </radius>
				</sphere>
			</geometry>
		</visual>

		<collision name = "butt_ball5_link_collision" >
			<geometry>
				<sphere>
					<radius> 0.1" </radius>
				</sphere>
			</geometry>
		</collision>
	</link>

	<link name = "butt_ball6_link" >
		<pose> -0.743750623750048 -0.31118324130874175 0.25 0 0 0 </pose>
		<inertial>
			<mass> 0.5 </mass>
			<inertia>
				<ixx> 0.0020000000000000005 </ixx>
				<ixy> 0.0 </ixy>
				<ixz> 0.0 </ixz>
				<iyy> 0.0020000000000000005 </iyy>
				<iyz> 0.0 </iyz>
				<izz> 0.0020000000000000005 </izz>
			</inertia>
		</inertial>

		<visual name = "butt_ball6_link_visual" >
			<geometry>
				<sphere>
					<radius> 0.1" </radius>
				</sphere>
			</geometry>
		</visual>

		<collision name = "butt_ball6_link_collision" >
			<geometry>
				<sphere>
					<radius> 0.1" </radius>
				</sphere>
			</geometry>
		</collision>
	</link>

	<link name = "top_ball1_link" >
		<pose> -0.6423496169447003 0.4872237367072718 2.075 0 0 2.0945 </pose>
		<inertial>
			<mass> 10 </mass>
			<inertia>
				<ixx> 0.04000000000000001 </ixx>
				<ixy> 0.0 </ixy>
				<ixz> 0.0 </ixz>
				<iyy> 0.04000000000000001 </iyy>
				<iyz> 0.0 </iyz>
				<izz> 0.04000000000000001 </izz>
			</inertia>
		</inertial>

		<visual name = "top_ball1_link_visual" >
			<geometry>
				<sphere>
					<radius> 0.1 </radius>
				</sphere>
			</geometry>
		</visual>

		<collision name = "top_ball1_link_collision" >
			<geometry>
				<sphere>
					<radius> 0.05" </radius>
				</sphere>
			</geometry>
		</collision>
	</link>

	<link name = "top_ball2_link" >
		<pose> 0.6421510948171859 0.4874853550878114 2.075 0 0 -2.0945 </pose>
		<inertial>
			<mass> 10 </mass>
			<inertia>
				<ixx> 0.04000000000000001 </ixx>
				<ixy> 0.0 </ixy>
				<ixz> 0.0 </ixz>
				<iyy> 0.04000000000000001 </iyy>
				<iyz> 0.0 </iyz>
				<izz> 0.04000000000000001 </izz>
			</inertia>
		</inertial>

		<visual name = "top_ball2_link_visual" >
			<geometry>
				<sphere>
					<radius> 0.1 </radius>
				</sphere>
			</geometry>
		</visual>

		<collision name = "top_ball2_link_collision" >
			<geometry>
				<sphere>
					<radius> 0.05" </radius>
				</sphere>
			</geometry>
		</collision>
	</link>

	<link name = "top_ball3_link" >
		<pose> 0.7429993434805581 0.3129728032712424 2.075 0 0 0 </pose>
		<inertial>
			<mass> 10 </mass>
			<inertia>
				<ixx> 0.04000000000000001 </ixx>
				<ixy> 0.0 </ixy>
				<ixz> 0.0 </ixz>
				<iyy> 0.04000000000000001 </iyy>
				<iyz> 0.0 </iyz>
				<izz> 0.04000000000000001 </izz>
			</inertia>
		</inertial>

		<visual name = "top_ball3_link_visual" >
			<geometry>
				<sphere>
					<radius> 0.1 </radius>
				</sphere>
			</geometry>
		</visual>

		<collision name = "top_ball3_link_collision" >
			<geometry>
				<sphere>
					<radius> 0.05" </radius>
				</sphere>
			</geometry>
		</collision>
	</link>

	<link name = "top_ball4_link" >
		<pose> 0.10046706791834908 -0.7999414780244177 2.075 0 0 2.0945 </pose>
		<inertial>
			<mass> 10 </mass>
			<inertia>
				<ixx> 0.04000000000000001 </ixx>
				<ixy> 0.0 </ixy>
				<ixz> 0.0 </ixz>
				<iyy> 0.04000000000000001 </iyy>
				<iyz> 0.0 </iyz>
				<izz> 0.04000000000000001 </izz>
			</inertia>
		</inertial>

		<visual name = "top_ball4_link_visual" >
			<geometry>
				<sphere>
					<radius> 0.1 </radius>
				</sphere>
			</geometry>
		</visual>

		<collision name = "top_ball4_link_collision" >
			<geometry>
				<sphere>
					<radius> 0.05" </radius>
				</sphere>
			</geometry>
		</collision>
	</link>

	<link name = "top_ball5_link" >
		<pose> -0.10108936054079155 -0.7998630765233847 2.075 0 0 -2.0945 </pose>
		<inertial>
			<mass> 10 </mass>
			<inertia>
				<ixx> 0.04000000000000001 </ixx>
				<ixy> 0.0 </ixy>
				<ixz> 0.0 </ixz>
				<iyy> 0.04000000000000001 </iyy>
				<iyz> 0.0 </iyz>
				<izz> 0.04000000000000001 </izz>
			</inertia>
		</inertial>

		<visual name = "top_ball5_link_visual" >
			<geometry>
				<sphere>
					<radius> 0.1 </radius>
				</sphere>
			</geometry>
		</visual>

		<collision name = "top_ball5_link_collision" >
			<geometry>
				<sphere>
					<radius> 0.05" </radius>
				</sphere>
			</geometry>
		</collision>
	</link>

	<link name = "top_ball6_link" >
		<pose> -0.7431267701815897 0.3126701191982996 2.075 0 0 0 </pose>
		<inertial>
			<mass> 10 </mass>
			<inertia>
				<ixx> 0.04000000000000001 </ixx>
				<ixy> 0.0 </ixy>
				<ixz> 0.0 </ixz>
				<iyy> 0.04000000000000001 </iyy>
				<iyz> 0.0 </iyz>
				<izz> 0.04000000000000001 </izz>
			</inertia>
		</inertial>

		<visual name = "top_ball6_link_visual" >
			<geometry>
				<sphere>
					<radius> 0.1 </radius>
				</sphere>
			</geometry>
		</visual>

		<collision name = "top_ball6_link_collision" >
			<geometry>
				<sphere>
					<radius> 0.05" </radius>
				</sphere>
			</geometry>
		</collision>
	</link>

	<link name = "piston1_cylinder_link" >
		<pose> -0.37312220398747875 0.6426976507881956 1.125 -0.33025008757600727 0 2.0945 </pose>
		<inertial>
			<mass> 3.5 </mass>
			<inertia>
				<ixx> 1.0941884339900043 </ixx>
				<ixy> 0.0 </ixy>
				<ixz> 0.0 </ixz>
				<iyy> 1.0941884339900043 </iyy>
				<iyz> 0.0 </iyz>
				<izz> 1.0941884339900043 </izz>
			</inertia>
		</inertial>

		<visual name = "piston1_cylinder_link_visual" >
			<geometry>
				<cylinder>
					<radius> 0.1 </radius>
					<length> 1.9291197998702527" </length>
				</cylinder>
			</geometry>
			<material>
				<!-- See: https://classic.gazebosim.org/tutorials?tut=color_model -->
		    <scene>
		      <ambient>0.9 0.9 0.9 1</ambient>
		      <background>0.25 0.25 0.25 1</background>
		      <shadows>false</shadows>
					<origin_visual>true</origin_visual>
		    </scene>
				<!-- See: http://sdformat.org/spec?ver=1.9&elem=light -->
		    <light type="directional" name="directional_light">
		      <diffuse>0.7 0.7 0.7 0</diffuse>
		      <specular>1 1 1 0</specular>
		      <direction>-1 -1 -1</direction>
		    </light>
			</material>

		</visual>

		<collision name = "piston1_link_collision" >
			<geometry>
				<cylinder>
					<radius> 0.1 </radius>
					<length> 1.9291197998702527" </length>
				</cylinder>
			</geometry>
		</collision>
	</link>

	<link name = "piston2_cylinder_link" >
		<pose> 0.37312220398747875 0.6426976507881956 1.125 -0.33025008757600727 0 -2.0945 </pose>
		<inertial>
			<mass> 3.5 </mass>
			<inertia>
				<ixx> 1.0941884339900043 </ixx>
				<ixy> 0.0 </ixy>
				<ixz> 0.0 </ixz>
				<iyy> 1.0941884339900043 </iyy>
				<iyz> 0.0 </iyz>
				<izz> 1.0941884339900043 </izz>
			</inertia>
		</inertial>

		<visual name = "piston2_cylinder_link_visual" >
			<geometry>
				<cylinder>
					<radius> 0.1 </radius>
					<length> 1.9291197998702527" </length>
				</cylinder>
			</geometry>
			<material>
				<!-- See: https://classic.gazebosim.org/tutorials?tut=color_model -->
		    <scene>
		      <ambient>0.9 0.9 0.9 1</ambient>
		      <background>0.25 0.25 0.25 1</background>
		      <shadows>false</shadows>
					<origin_visual>true</origin_visual>
		    </scene>
				<!-- See: http://sdformat.org/spec?ver=1.9&elem=light -->
		    <light type="directional" name="directional_light">
		      <diffuse>0.7 0.7 0.7 0</diffuse>
		      <specular>1 1 1 0</specular>
		      <direction>-1 -1 -1</direction>
		    </light>
			</material>
		</visual>

		<collision name = "piston2_link_collision" >
			<geometry>
				<cylinder>
					<radius> 0.1 </radius>
					<length> 1.9291197998702527" </length>
				</cylinder>
			</geometry>
		</collision>
	</link>

	<link name = "piston3_cylinder_link" >
		<pose> 0.7431557370007575 0 1.125 -0.33025008757600727 0 0 </pose>
		<inertial>
			<mass> 3.5 </mass>
			<inertia>
				<ixx> 1.0941884339900043 </ixx>
				<ixy> 0.0 </ixy>
				<ixz> 0.0 </ixz>
				<iyy> 1.0941884339900043 </iyy>
				<iyz> 0.0 </iyz>
				<izz> 1.0941884339900043 </izz>
			</inertia>
		</inertial>

		<visual name = "piston3_cylinder_link_visual" >
			<geometry>
				<cylinder>
					<radius> 0.1 </radius>
					<length> 1.9291197998702527" </length>
				</cylinder>
			</geometry>
			<material>
				<!-- See: https://classic.gazebosim.org/tutorials?tut=color_model -->
		    <scene>
		      <ambient>0.9 0.9 0.9 1</ambient>
		      <background>0.25 0.25 0.25 1</background>
		      <shadows>false</shadows>
					<origin_visual>true</origin_visual>
		    </scene>
				<!-- See: http://sdformat.org/spec?ver=1.9&elem=light -->
		    <light type="directional" name="directional_light">
		      <diffuse>0.7 0.7 0.7 0</diffuse>
		      <specular>1 1 1 0</specular>
		      <direction>-1 -1 -1</direction>
		    </light>
			</material>
		</visual>

		<collision name = "piston3_link_collision" >
			<geometry>
				<cylinder>
					<radius> 0.1 </radius>
					<length> 1.9291197998702527" </length>
				</cylinder>
			</geometry>
		</collision>
	</link>

	<link name = "piston4_cylinder_link" >
		<pose> 0.3717050035686465 -0.6435183290001705 1.125 -0.33025008757600727 0 2.0945 </pose>
		<inertial>
			<mass> 3.5 </mass>
			<inertia>
				<ixx> 1.0941884339900043 </ixx>
				<ixy> 0.0 </ixy>
				<ixz> 0.0 </ixz>
				<iyy> 1.0941884339900043 </iyy>
				<iyz> 0.0 </iyz>
				<izz> 1.0941884339900043 </izz>
			</inertia>
		</inertial>

		<visual name = "piston4_cylinder_link_visual" >
			<geometry>
				<cylinder>
					<radius> 0.1 </radius>
					<length> 1.9291197998702527" </length>
				</cylinder>
			</geometry>
			<material>
		    <scene>
		      <ambient>0.9 0.9 0.9 1</ambient>
		      <background>0.25 0.25 0.25 1</background>
		      <shadows>false</shadows>
					<origin_visual>true</origin_visual>
		    </scene>
		    <light type="directional" name="directional_light">
		      <diffuse>0.7 0.7 0.7 0</diffuse>
		      <specular>1 1 1 0</specular>
		      <direction>-1 -1 -1</direction>
		    </light>
			</material>
		</visual>

		<collision name = "piston4_link_collision" >
			<geometry>
				<cylinder>
					<radius> 0.1 </radius>
					<length> 1.9291197998702527" </length>
				</cylinder>
			</geometry>
		</collision>
	</link>

	<link name = "piston5_cylinder_link" >
		<pose> -0.3713235548646821 -0.6437385082778523 1.125 -0.33025008757600727 0 -2.0945 </pose>
		<inertial>
			<mass> 3.5 </mass>
			<inertia>
				<ixx> 1.0941884339900043 </ixx>
				<ixy> 0.0 </ixy>
				<ixz> 0.0 </ixz>
				<iyy> 1.0941884339900043 </iyy>
				<iyz> 0.0 </iyz>
				<izz> 1.0941884339900043 </izz>
			</inertia>
		</inertial>

		<visual name = "piston5_cylinder_link_visual" >
			<geometry>
				<cylinder>
					<radius> 0.1 </radius>
					<length> 1.9291197998702527" </length>
				</cylinder>
			</geometry>
			<material>
				<!-- See: https://classic.gazebosim.org/tutorials?tut=color_model -->
		    <scene>
		      <ambient>0.9 0.9 0.9 1</ambient>
		      <background>0.25 0.25 0.25 1</background>
		      <shadows>false</shadows>
					<origin_visual>true</origin_visual>
		    </scene>
				<!-- See: http://sdformat.org/spec?ver=1.9&elem=light -->
		    <light type="directional" name="directional_light">
		      <diffuse>0.7 0.7 0.7 0</diffuse>
		      <specular>1 1 1 0</specular>
		      <direction>-1 -1 -1</direction>
		    </light>
			</material>
		</visual>

		<collision name = "piston5_link_collision" >
			<geometry>
				<cylinder>
					<radius> 0.1 </radius>
					<length> 1.9291197998702527" </length>
				</cylinder>
			</geometry>
		</collision>
	</link>

	<link name = "piston6_cylinder_link" >
		<pose> -0.7431557370007575 0 1.125 -0.33025008757600727 0 0 </pose>
		<inertial>
			<mass> 3.5 </mass>
			<inertia>
				<ixx> 1.0941884339900043 </ixx>
				<ixy> 0.0 </ixy>
				<ixz> 0.0 </ixz>
				<iyy> 1.0941884339900043 </iyy>
				<iyz> 0.0 </iyz>
				<izz> 1.0941884339900043 </izz>
			</inertia>
		</inertial>

		<visual name = "piston6_cylinder_link_visual" >
			<geometry>
				<cylinder>
					<radius> 0.1 </radius>
					<length> 1.9291197998702527" </length>
				</cylinder>
			</geometry>
			<material>
				<!-- See: https://classic.gazebosim.org/tutorials?tut=color_model -->
		    <scene>
		      <ambient>0.9 0.9 0.9 1</ambient>
		      <background>0.25 0.25 0.25 1</background>
		      <shadows>false</shadows>
					<origin_visual>true</origin_visual>
		    </scene>
				<!-- See: http://sdformat.org/spec?ver=1.9&elem=light -->
		    <light type="directional" name="directional_light">
		      <diffuse>0.7 0.7 0.7 0</diffuse>
		      <specular>1 1 1 0</specular>
		      <direction>-1 -1 -1</direction>
		    </light>
			</material>
		</visual>

		<collision name = "piston6_link_collision" >
			<geometry>
				<cylinder>
					<radius> 0.1 </radius>
					<length> 1.9291197998702527" </length>
				</cylinder>
			</geometry>
		</collision>
	</link>

	<link name = "piston1_shaft_link" >
		<pose> -0.37312220398747875 0.6426976507881956 1.125 -0.33025008757600727 0 2.0945 </pose>
		<inertial>
			<mass> 2.5 </mass>
			<inertia>
				<ixx> 0.7768756671357173 </ixx>
				<ixy> 0.0 </ixy>
				<ixz> 0.0 </ixz>
				<iyy> 0.7768756671357173 </iyy>
				<iyz> 0.0 </iyz>
				<izz> 0.7768756671357173 </izz>
			</inertia>
		</inertial>

		<visual name = "piston1_shaft_visual" >
			<geometry>
				<cylinder>
					<radius> 0.05" </radius>
					<length> 1.9291197998702527" </length>
				</cylinder>
			</geometry>
			<material>
				<script>
					<uri>file://media/materials/scripts/gazebo.material</uri>
					<name>Gazebo/Blue</name>
				</script>
			</material>
		</visual>

		<collision name = "piston1_shaft_collision" >
			<geometry>
				<cylinder>
					<radius> 0.05" </radius>
					<length> 1.9291197998702527" </length>
				</cylinder>
			</geometry>
		</collision>
	</link>

	<link name = "piston2_shaft_link" >
		<pose> 0.37312220398747875 0.6426976507881956 1.125 -0.33025008757600727 0 -2.0945 </pose>
		<inertial>
			<mass> 2.5 </mass>
			<inertia>
				<ixx> 0.7768756671357173 </ixx>
				<ixy> 0.0 </ixy>
				<ixz> 0.0 </ixz>
				<iyy> 0.7768756671357173 </iyy>
				<iyz> 0.0 </iyz>
				<izz> 0.7768756671357173 </izz>
			</inertia>
		</inertial>

		<visual name = "piston2_shaft_visual" >
			<geometry>
				<cylinder>
					<radius> 0.05" </radius>
					<length> 1.9291197998702527" </length>
				</cylinder>
			</geometry>
			<material>
				<script>
					<uri>file://media/materials/scripts/gazebo.material</uri>
					<name>Gazebo/Blue</name>
				</script>
			</material>
		</visual>

		<collision name = "piston2_shaft_collision" >
			<geometry>
				<cylinder>
					<radius> 0.05" </radius>
					<length> 1.9291197998702527" </length>
				</cylinder>
			</geometry>
		</collision>
	</link>

	<link name = "piston3_shaft_link" >
		<pose> 0.7431557370007575 0 1.125 -0.33025008757600727 0 0 </pose>
		<inertial>
			<mass> 2.5 </mass>
			<inertia>
				<ixx> 0.7768756671357173 </ixx>
				<ixy> 0.0 </ixy>
				<ixz> 0.0 </ixz>
				<iyy> 0.7768756671357173 </iyy>
				<iyz> 0.0 </iyz>
				<izz> 0.7768756671357173 </izz>
			</inertia>
		</inertial>

		<visual name = "piston3_shaft_visual" >
			<geometry>
				<cylinder>
					<radius> 0.05" </radius>
					<length> 1.9291197998702527" </length>
				</cylinder>
			</geometry>
			<material>
				<script>
					<uri>file://media/materials/scripts/gazebo.material</uri>
					<name>Gazebo/Blue</name>
				</script>
			</material>
		</visual>

		<collision name = "piston3_shaft_collision" >
			<geometry>
				<cylinder>
					<radius> 0.05" </radius>
					<length> 1.9291197998702527" </length>
				</cylinder>
			</geometry>
		</collision>
	</link>

	<link name = "piston4_shaft_link" >
		<pose> 0.3717050035686465 -0.6435183290001705 1.125 -0.33025008757600727 0 2.0945 </pose>
		<inertial>
			<mass> 2.5 </mass>
			<inertia>
				<ixx> 0.7768756671357173 </ixx>
				<ixy> 0.0 </ixy>
				<ixz> 0.0 </ixz>
				<iyy> 0.7768756671357173 </iyy>
				<iyz> 0.0 </iyz>
				<izz> 0.7768756671357173 </izz>
			</inertia>
		</inertial>

		<visual name = "piston4_shaft_visual" >
			<geometry>
				<cylinder>
					<radius> 0.05" </radius>
					<length> 1.9291197998702527" </length>
				</cylinder>
			</geometry>
			<material>
				<script>
					<uri>file://media/materials/scripts/gazebo.material</uri>
					<name>Gazebo/Blue</name>
				</script>
			</material>
		</visual>

		<collision name = "piston4_shaft_collision" >
			<geometry>
				<cylinder>
					<radius> 0.05" </radius>
					<length> 1.9291197998702527" </length>
				</cylinder>
			</geometry>
		</collision>
	</link>

	<link name = "piston5_shaft_link" >
		<pose> -0.3713235548646821 -0.6437385082778523 1.125 -0.33025008757600727 0 -2.0945 </pose>
		<inertial>
			<mass> 2.5 </mass>
			<inertia>
				<ixx> 0.7768756671357173 </ixx>
				<ixy> 0.0 </ixy>
				<ixz> 0.0 </ixz>
				<iyy> 0.7768756671357173 </iyy>
				<iyz> 0.0 </iyz>
				<izz> 0.7768756671357173 </izz>
			</inertia>
		</inertial>

		<visual name = "piston5_shaft_visual" >
			<geometry>
				<cylinder>
					<radius> 0.05" </radius>
					<length> 1.9291197998702527" </length>
				</cylinder>
			</geometry>
			<material>
				<script>
					<uri>file://media/materials/scripts/gazebo.material</uri>
					<name>Gazebo/Blue</name>
				</script>
			</material>
		</visual>

		<collision name = "piston5_shaft_collision" >
			<geometry>
				<cylinder>
					<radius> 0.05" </radius>
					<length> 1.9291197998702527" </length>
				</cylinder>
			</geometry>
		</collision>
	</link>

	<link name = "piston6_shaft_link" >
		<pose> -0.7431557370007575 0 1.125 -0.33025008757600727 0 0 </pose>
		<inertial>
			<mass> 2.5 </mass>
			<inertia>
				<ixx> 0.7768756671357173 </ixx>
				<ixy> 0.0 </ixy>
				<ixz> 0.0 </ixz>
				<iyy> 0.7768756671357173 </iyy>
				<iyz> 0.0 </iyz>
				<izz> 0.7768756671357173 </izz>
			</inertia>
		</inertial>

		<visual name = "piston6_shaft_visual" >
			<geometry>
				<cylinder>
					<radius> 0.05" </radius>
					<length> 1.9291197998702527" </length>
				</cylinder>
			</geometry>
			<material>
				<script>
					<uri>file://media/materials/scripts/gazebo.material</uri>
					<name>Gazebo/Blue</name>
				</script>
			</material>
		</visual>

		<collision name = "piston6_shaft_collision" >
			<geometry>
				<cylinder>
					<radius> 0.05" </radius>
					<length> 1.9291197998702527" </length>
				</cylinder>
			</geometry>
		</collision>
	</link>

	<!-- Add arm to platform -->
  <!-- <joint name = "arm_base_platform_joint" type = "fixed" >
    <parent> platform_link </parent>
    <child>arm::arm_base_link </child>
    <pose> 0 0 0 0 0 0  </pose>
  </joint> -->

</model>
</sdf>
